Traceback (most recent call last):
  File "track.py", line 41, in <module>
    cv2.CHAIN_APPROX_SIMPLE)
ValueError: not enough values to unpack (expected 3, got 2)

  --------------------------
  这里好像是和python（ 或者opencv版本）  有关
  
  我在执行 python3 时候遇到了 但是python2没有遇到
